Workbook

Sheet NBFC-Vehicle Finance
C2: NBFC - VEHICLE FINANCE
C3: IKF Finance | G3: Cholamandalam | K3: SK Finance | N3: Shriram Finance | T3: Indostar Capital Finance
C4: ='IKF Finance'!C3 -> FY23 | D4: ='IKF Finance'!D3 -> FY24 | E4: ='IKF Finance'!E3 -> FY25 | F4: ='IKF Finance'!F3 -> FY26 | G4: FY23 | H4: FY24 | I4: FY25 | J4: FY26 | K4: FY 24 | L4: FY 25 | M4: FY 26 | N4: FY 21 | O4: FY 22 | P4: FY 23 | Q4: FY 24 | R4: FY 25 | S4: FY 26 | T4: FY 23 | U4: FY 24 | V4: FY 25 | W4: FY 26
B5: Particulars | C5: ='IKF Finance'!C4 -> Aud | D5: ='IKF Finance'!D4 -> Aud | E5: ='IKF Finance'!E4 -> Aud | F5: ='IKF Finance'!F4 -> Aud | G5: Aud | J5: Aud | K5: Aud | L5: Aud | M5: Aud | N5: Aud | O5: Aud | P5: Aud | Q5: Aud | R5: Aud | S5: Aud | T5: Aud | U5: Aud | V5: Aud | W5: Aud
C6: Rs in Crores | G6: Rs in Crores | K6: Rs in Crores | N6: Rs in Crore | T6: Rs in Crores
B7: Revenue from operations | C7: ='IKF Finance'!C6 -> 287 | D7: ='IKF Finance'!D6 -> 437 | E7: ='IKF Finance'!E6 -> 660 | F7: ='IKF Finance'!F6 -> 908 | G7: ='Cholamandalam Inv & Fin'!C6 -> 12757 | H7: ='Cholamandalam Inv & Fin'!D6 -> 18845 | I7: ='Cholamandalam Inv & Fin'!E6 -> 25746 | J7: ='Cholamandalam Inv & Fin'!F6 -> 30982 | K7: ='SK Finance'!C6 -> 1791 | L7: ='SK Finance'!D6 -> 2378 | M7: ='SK Finance'!E6 -> 2824 | N7: 17420.45 | O7: 19255.17 | P7: ='Shriram Finance'!E6 -> 29772.16 | Q7: 34964 | R7: 41834 | S7: 48118 | T7: ='Indostar Capital '!C6 -> 969 | U7: ='Indostar Capital '!D6 -> 1104 | V7: ='Indostar Capital '!E6 -> 1404 | W7: ='Indostar Capital '!F6 -> 1392.8917
B8: Interest Income | C8: ='IKF Finance'!C7 -> 284 | D8: ='IKF Finance'!D7 -> 421 | E8: ='IKF Finance'!E7 -> 618 | F8: ='IKF Finance'!F7 -> 855 | G8: ='Cholamandalam Inv & Fin'!C7 -> 12082 | H8: ='Cholamandalam Inv & Fin'!D7 -> 17614 | I8: ='Cholamandalam Inv & Fin'!E7 -> 23720 | J8: ='Cholamandalam Inv & Fin'!F7 -> 28373 | K8: ='SK Finance'!C7 -> 1499 | L8: ='SK Finance'!D7 -> 1899 | M8: ='SK Finance'!E7 -> 2262 | N8: 16611.31 | O8: 18028.13 | P8: ='Shriram Finance'!E7 -> 27504.2 | Q8: 33600 | R8: 40308 | S8: 46644 | T8: ='Indostar Capital '!C7 -> 864 | U8: ='Indostar Capital '!D7 -> 876 | V8: ='Indostar Capital '!E7 -> 1153 | W8: ='Indostar Capital '!F7 -> 1262.5166
B9: Other Operation Income | C9: ='IKF Finance'!C9 -> 3 | D9: ='IKF Finance'!D9 -> 4 | E9: ='IKF Finance'!E9 -> 7 | F9: ='IKF Finance'!F9 -> 8 | G9: ='Cholamandalam Inv & Fin'!C9 -> 674 | H9: ='Cholamandalam Inv & Fin'!D9 -> 1232 | I9: ='Cholamandalam Inv & Fin'!E9 -> 2025 | J9: ='Cholamandalam Inv & Fin'!F9 -> 2609 | K9: ='SK Finance'!C9 -> 97 | L9: ='SK Finance'!D9 -> 161 | M9: ='SK Finance'!E9 -> 215 | N9: =N7-N8 -> 809.14 | O9: =O7-O8 -> 1227.04 | P9: ='Shriram Finance'!E9 -> 2267.96 | Q9: =Q7-Q8 -> 1364 | R9: =R7-R8 -> 1526 | S9: =S7-S8 -> 1474 | T9: =SUM('Indostar Capital '!C8:C9) -> 105 | U9: =SUM('Indostar Capital '!D8:D9) -> 228 | V9: =SUM('Indostar Capital '!E8:E9) -> 251 | W9: =SUM('Indostar Capital '!F8:F9) -> 130.3751
B10: Interest expended | C10: ='IKF Finance'!C10 -> 154 | D10: ='IKF Finance'!D10 -> 220 | E10: ='IKF Finance'!E10 -> 332 | F10: ='IKF Finance'!F10 -> 417 | G10: ='Cholamandalam Inv & Fin'!C10 -> 5749 | H10: ='Cholamandalam Inv & Fin'!D10 -> 9231 | I10: ='Cholamandalam Inv & Fin'!E10 -> 12485 | J10: ='Cholamandalam Inv & Fin'!F10 -> 14374 | K10: ='SK Finance'!C10 -> 747 | L10: ='SK Finance'!D10 -> 971 | M10: ='SK Finance'!E10 -> 1119 | N10: 9054.26 | O10: 9734.31 | P10: ='Shriram Finance'!E10 -> 12545.76 | Q10: 14806 | R10: 18455 | S10: 21520 | T10: ='Indostar Capital '!C10 -> 518 | U10: ='Indostar Capital '!D10 -> 581 | V10: ='Indostar Capital '!E10 -> 741 | W10: ='Indostar Capital '!F10 -> 621.16
B11: Net Interest Income | C11: =C8-C10 -> 130 | D11: =D8-D10 -> 201 | E11: =E8-E10 -> 286 | F11: =F8-F10 -> 438 | G11: ='Cholamandalam Inv & Fin'!C11 -> 6333 | H11: ='Cholamandalam Inv & Fin'!D11 -> 8383 | I11: ='Cholamandalam Inv & Fin'!E11 -> 11235 | J11: ='Cholamandalam Inv & Fin'!F11 -> 13998 | K11: ='SK Finance'!C11 -> 752 | L11: ='SK Finance'!D11 -> 928 | M11: ='SK Finance'!E11 -> 1142 | N11: =N8-N10 -> 7557.05 | O11: =O8-O10 -> 8293.82 | P11: ='Shriram Finance'!E11 -> 14958.44 | Q11: =Q8-Q10 -> 18794 | R11: =R8-R10 -> 21853 | S11: =S8-S10 -> 25124 | T11: ='Indostar Capital '!C11 -> 346 | U11: ='Indostar Capital '!D11 -> 295 | V11: ='Indostar Capital '!E11 -> 412 | W11: ='Indostar Capital '!F11 -> 641.3566
B12: Total Operating Income | C12: =C8+C9 -> 287 | D12: =D8+D9 -> 425 | E12: =E8+E9 -> 625 | F12: =F8+F9 -> 863 | G12: =G8+G9 -> 12756 | H12: =H8+H9 -> 18846 | I12: =I8+I9 -> 25745 | J12: =J8+J9 -> 30982 | ... M12: =M8+M9 -> 2477 | N12: =SUM(N8:N9) -> 17420.45 | O12: =SUM(O8:O9) -> 19255.17 | P12: ='Shriram Finance'!E12 -> 29772.16 | Q12: =SUM(Q8:Q9) -> 34964 | R12: =SUM(R8:R9) -> 41834 | S12: =SUM(S8:S9) -> 48118 | T12: =T8+T9 -> 969 | U12: =U8+U9 -> 1104 | V12: =V8+V9 -> 1404 | W12: =W8+W9 -> 1392.8917
B13: Other income | C13: ='IKF Finance'!C13 -> 0 | D13: ='IKF Finance'!D13 -> 12 | E13: ='IKF Finance'!E13 -> 35 | F13: ='IKF Finance'!F13 -> 46 | G13: ='Cholamandalam Inv & Fin'!C13 -> 221 | H13: ='Cholamandalam Inv & Fin'!D13 -> 371 | I13: ='Cholamandalam Inv & Fin'!E13 -> 309 | J13: ='Cholamandalam Inv & Fin'!F13 -> 463 | K13: ='SK Finance'!C13 -> 6.7545 | L13: ='SK Finance'!D13 -> 8 | M13: ='SK Finance'!E13 -> 4 | N13: 15.95 | O13: 19.06 | P13: ='Shriram Finance'!E13 -> 30.73 | Q13: 33.2 | R13: 25.05 | S13: 60 | T13: ='Indostar Capital '!C13 -> 24 | U13: ='Indostar Capital '!D13 -> 21 | V13: ='Indostar Capital '!E13 -> 8 | W13: ='Indostar Capital '!F13 -> 1
B14: Total Income | C14: =C12+C13 -> 287 | D14: =D12+D13 -> 437 | E14: =E12+E13 -> 660 | F14: =F12+F13 -> 909 | G14: =G12+G13 -> 12977 | H14: =H12+H13 -> 19217 | I14: =I12+I13 -> 26054 | J14: =J12+J13 -> 31445 | ... W14: =W12+W13 -> 1393.8917
B15: Operating expenses | C15: ='IKF Finance'!C15 -> 60 | D15: ='IKF Finance'!D15 -> 97 | E15: ='IKF Finance'!E15 -> 144 | F15: ='IKF Finance'!F15 -> 186 | G15: ='Cholamandalam Inv & Fin'!C15 -> 2780 | H15: ='Cholamandalam Inv & Fin'!D15 -> 4082 | I15: ='Cholamandalam Inv & Fin'!E15 -> 5339 | J15: ='Cholamandalam Inv & Fin'!F15 -> 6574 | K15: ='SK Finance'!C15 -> 531.852 | L15: ='SK Finance'!D15 -> 688 | M15: ='SK Finance'!E15 -> 816 | N15: =906.25+137.36+863.23+78.89 -> 1985.73 | O15: =997.09+135.37+905.61+91.74 -> 2129.81 | P15: 4913.07 | Q15: 5990 | R15: 7143 | S15: 8027 | T15: ='Indostar Capital '!C15 -> 328 | U15: ='Indostar Capital '!D15 -> 389 | V15: ='Indostar Capital '!E15 -> 481 | W15: ='Indostar Capital '!F15 -> 505.9526
B16: Operating profit before finance costs | C16: ='IKF Finance'!C16 -> 227 | D16: ='IKF Finance'!D16 -> 328 | E16: ='IKF Finance'!E16 -> 481 | F16: ='IKF Finance'!F16 -> 677 | G16: ='Cholamandalam Inv & Fin'!C16 -> 9976 | H16: ='Cholamandalam Inv & Fin'!D16 -> 14764 | I16: ='Cholamandalam Inv & Fin'!E16 -> 20406 | J16: ='Cholamandalam Inv & Fin'!F16 -> 24408 | K16: ='SK Finance'!C16 -> 1259.148 | L16: ='SK Finance'!D16 -> 1690 | M16: ='SK Finance'!E16 -> 2008 | N16: =N12-N15 -> 15434.72 | O16: =O12-O15 -> 17125.36 | P16: 24859.09 | Q16: =Q12-Q15 -> 28974 | R16: =R12-R15 -> 34691 | S16: =S12-S15 -> 40091 | T16: =T12-T15 -> 641 | U16: =U12-U15 -> 715 | V16: =V12-V15 -> 923 | W16: =W12-W15 -> 886.9391
B17: Pre-provisioning operating profit | C17: ='IKF Finance'!C17 -> 73 | D17: ='IKF Finance'!D17 -> 108 | E17: ='IKF Finance'!E17 -> 149 | F17: ='IKF Finance'!F17 -> 260 | G17: ='Cholamandalam Inv & Fin'!C17 -> 4227 | H17: ='Cholamandalam Inv & Fin'!D17 -> 5533 | I17: ='Cholamandalam Inv & Fin'!E17 -> 7921 | J17: ='Cholamandalam Inv & Fin'!F17 -> 10034 | K17: ='SK Finance'!C17 -> 512.148 | L17: ='SK Finance'!D17 -> 719 | M17: ='SK Finance'!E17 -> 889 | N17: =N14-N15-N10 -> 6396.41 | O17: =O14-O15-O10 -> 7410.11 | P17: =P14-P15-P10 -> 12344.06 | Q17: =Q14-Q15-Q10 -> 14201.2 | R17: =R14-R15-R10 -> 16261.05 | S17: =S14-S15-S10 -> 18631 | T17: =T16-T10 -> 123 | U17: =U16-U10 -> 134 | V17: =V16-V10 -> 182 | W17: =W16-W10 -> 265.7791
B18: Provisions | C18: ='IKF Finance'!C18 -> 5 | D18: ='IKF Finance'!D18 -> 16 | E18: ='IKF Finance'!E18 -> 40 | F18: ='IKF Finance'!F18 -> 84 | G18: ='Cholamandalam Inv & Fin'!C18 -> 850 | H18: ='Cholamandalam Inv & Fin'!D18 -> 1322 | I18: ='Cholamandalam Inv & Fin'!E18 -> 2494 | J18: ='Cholamandalam Inv & Fin'!F18 -> 3536 | K18: ='SK Finance'!C18 -> 119.4335 | L18: ='SK Finance'!D18 -> 239 | M18: ='SK Finance'!E18 -> 326 | N18: 3118.4 | O18: 3860.86 | P18: 4159 | Q18: 4518 | R18: 5312 | S18: 5339 | T18: ='Indostar Capital '!C18 -> -40 | U18: ='Indostar Capital '!D18 -> 83 | V18: ='Indostar Capital '!E18 -> 138 | W18: ='Indostar Capital '!F18 -> 621
B19: PAT | C19: ='IKF Finance'!C19 -> 50 | D19: ='IKF Finance'!D19 -> 77 | E19: ='IKF Finance'!E19 -> 108 | F19: ='IKF Finance'!F19 -> 165 | G19: ='Cholamandalam Inv & Fin'!C19 -> 2666 | H19: ='Cholamandalam Inv & Fin'!D19 -> 3423 | I19: ='Cholamandalam Inv & Fin'!E19 -> 4259 | J19: ='Cholamandalam Inv & Fin'!F19 -> 5220 | K19: ='SK Finance'!C19 -> 311.9233 | L19: ='SK Finance'!D19 -> 380 | M19: ='SK Finance'!E19 -> 431 | N19: 2487.26 | O19: 2707.93 | P19: 5979 | Q19: 7190 | R19: 9761 | S19: 9998 | T19: ='Indostar Capital '!C19 -> 187 | U19: ='Indostar Capital '!D19 -> 72 | V19: ='Indostar Capital '!E19 -> 53 | W19: ='Indostar Capital '!F19 -> 130.2015
B20: TNW | C20: ='IKF Finance'!C20 -> 691 | D20: ='IKF Finance'!D20 -> 879 | E20: ='IKF Finance'!E20 -> 987 | F20: ='IKF Finance'!F20 -> 1895 | G20: ='Cholamandalam Inv & Fin'!C20 -> 13637 | H20: ='Cholamandalam Inv & Fin'!D20 -> 18867 | I20: ='Cholamandalam Inv & Fin'!E20 -> 22649 | J20: ='Cholamandalam Inv & Fin'!F20 -> 29203 | K20: ='SK Finance'!C20 -> 3075.2917 | L20: ='SK Finance'!D20 -> 3479 | M20: ='SK Finance'!E20 -> 3953 | N20: 21568.37 | O20: 25932.19 | P20: 43306.64 | Q20: 43244 | R20: 50698 | S20: 59916 | T20: ='Indostar Capital '!C20 -> 2386 | U20: ='Indostar Capital '!D20 -> 2475 | V20: ='Indostar Capital '!E20 -> 2804 | W20: ='Indostar Capital '!F20 -> 3156
B21: Total Debt | C21: ='IKF Finance'!C22 -> 2037 | D21: ='IKF Finance'!D22 -> 2733 | E21: ='IKF Finance'!E22 -> 3927 | F21: ='IKF Finance'!F22 -> 4743 | G21: ='Cholamandalam Inv & Fin'!C22 -> 97356 | H21: ='Cholamandalam Inv & Fin'!D22 -> 134474 | I21: ='Cholamandalam Inv & Fin'!E22 -> 175036 | J21: ='Cholamandalam Inv & Fin'!F22 -> 210867 | K21: ='SK Finance'!C22 -> 8934.8797 | L21: ='SK Finance'!D22 -> 11604 | M21: ='SK Finance'!E22 -> 12820 | N21: =40061.87+45281.37+16232.41+4620.76 -> 106196.41 | O21: =41256.55+46676.93+21948.98+4614.25 -> 114496.71 | P21: 157906.29 | Q21: 185841 | R21: 234472 | S21: 250748 | T21: ='Indostar Capital '!C22 -> 4813 | U21: ='Indostar Capital '!D22 -> 6049 | V21: ='Indostar Capital '!E22 -> 6916 | W21: ='Indostar Capital '!F22 -> 5476.8355
B22: Total Assets | C22: ='IKF Finance'!C23 -> 2764 | D22: ='IKF Finance'!D23 -> 3676 | E22: ='IKF Finance'!E23 -> 5012 | F22: ='IKF Finance'!F23 -> 6757 | G22: ='Cholamandalam Inv & Fin'!C23 -> 113516 | H22: ='Cholamandalam Inv & Fin'!D23 -> 156451 | I22: ='Cholamandalam Inv & Fin'!E23 -> 201648 | J22: ='Cholamandalam Inv & Fin'!F23 -> 245070 | K22: ='SK Finance'!C23 -> 12309.122 | L22: ='SK Finance'!D23 -> 15419 | M22: ='SK Finance'!E23 -> 17152 | N22: 129761.34 | O22: 142106.09 | P22: 203663.86 | Q22: 237276 | R22: 293808 | S22: 321155 | T22: ='Indostar Capital '!C23 -> 8139 | U22: ='Indostar Capital '!D23 -> 9390 | V22: ='Indostar Capital '!E23 -> 10762 | W22: ='Indostar Capital '!F23 -> 9511.4377
B23: Loans & Advances (Gross) | C23: ='IKF Finance'!C24 -> 2137 | D23: ='IKF Finance'!D24 -> 3291 | E23: ='IKF Finance'!E24 -> 4574 | F23: ='IKF Finance'!F24 -> 5873 | G23: ='Cholamandalam Inv & Fin'!C24 -> 104748 | H23: ='Cholamandalam Inv & Fin'!D24 -> 144424 | I23: ='Cholamandalam Inv & Fin'!E24 -> 181930 | J23: ='Cholamandalam Inv & Fin'!F24 -> 217571 | K23: ='SK Finance'!C24 -> 9813.4221 | L23: ='SK Finance'!D24 -> 12074 | M23: ='SK Finance'!E24 -> 14154 | N23: 116191.59 | O23: 125699.03 | P23: 183338.42 | Q23: 221668 | R23: 259916 | S23: 300216 | T23: ='Indostar Capital '!C24 -> 5737 | U23: ='Indostar Capital '!D24 -> 6298 | V23: ='Indostar Capital '!E24 -> 7464 | W23: ='Indostar Capital '!F24 -> 7850.1015
B24: Gross NPAs | C24: ='IKF Finance'!C25 -> 61 | D24: ='IKF Finance'!D25 -> 77 | E24: ='IKF Finance'!E25 -> 103 | F24: ='IKF Finance'!F25 -> 148 | G24: ='Cholamandalam Inv & Fin'!C25 -> 4953 | H24: ='Cholamandalam Inv & Fin'!D25 -> 5205 | I24: ='Cholamandalam Inv & Fin'!E25 -> 5213 | J24: ='Cholamandalam Inv & Fin'!F25 -> 6767 | K24: ='SK Finance'!C25 -> 343.3181 | L24: ='SK Finance'!D25 -> 573 | M24: ='SK Finance'!E25 -> 614 | N24: 8292.81 | O24: 8887.55 | P24: 11382.18 | Q24: 12081 | R24: 11839 | S24: 13743 | T24: ='Indostar Capital '!C25 -> 462 | U24: ='Indostar Capital '!D25 -> 313 | V24: ='Indostar Capital '!E25 -> 337 | W24: ='Indostar Capital '!F25 -> 374.6938
B25: Net NPAs | C25: ='IKF Finance'!C26 -> 48 | D25: ='IKF Finance'!D26 -> 59 | E25: ='IKF Finance'!E26 -> 68 | F25: ='IKF Finance'!F26 -> 98 | G25: ='Cholamandalam Inv & Fin'!C26 -> 3281 | H25: ='Cholamandalam Inv & Fin'!D26 -> 3374 | I25: ='Cholamandalam Inv & Fin'!E26 -> 2853 | J25: ='Cholamandalam Inv & Fin'!F26 -> 3567 | K25: ='SK Finance'!C26 -> 239.5362 | L25: ='SK Finance'!D26 -> 407 | M25: ='SK Finance'!E26 -> 401 | N25: 4806.68 | O25: 4446.05 | P25: 5674.91 | Q25: 5824 | R25: 6714 | S25: 6825 | T25: ='Indostar Capital '!C26 -> 207 | U25: ='Indostar Capital '!D26 -> 128 | V25: ='Indostar Capital '!E26 -> 180 | W25: ='Indostar Capital '!F26 -> 159.6127
C27: ='IKF Finance'!J3 -> FY23(A) | D27: ='IKF Finance'!K3 -> FY24 (A) | E27: ='IKF Finance'!L3 -> FY25 (A) | F27: ='IKF Finance'!M3 -> FY26 (A) | G27: ='Cholamandalam Inv & Fin'!K2 -> FY23 (A) | H27: ='Cholamandalam Inv & Fin'!L2 -> FY24 (A) | I27: ='Cholamandalam Inv & Fin'!M2 -> FY25 (A) | J27: ='Cholamandalam Inv & Fin'!N2 -> FY26 (A) | K27: FY24 (A) | L27: FY25 (A) | M27: FY26 (A) | N27: FY21 (A) | O27: FY22 (A) | P27: FY23 (A) | Q27: FY24 (A) | R27: FY25 (A) | S27: FY26 (A) | T27: FY23 (A) | U27: FY24 (A) | V27: FY25 (A) | W27: FY26 (A)
B28: Profitability
B29: Net Interest Margin | C29: ='IKF Finance'!J5 -> 0.060832943 | D29: ='IKF Finance'!K5 -> 0.074060427 | E29: ='IKF Finance'!L5 -> 0.072727273 | F29: ='IKF Finance'!M5 -> 0.083851823 | G29: ='Cholamandalam Inv & Fin'!K4 -> 0.060459388 | H29: ='Cholamandalam Inv & Fin'!L4 -> 0.067286854 | I29: ='Cholamandalam Inv & Fin'!M4 -> 0.068851615 | J29: ='Cholamandalam Inv & Fin'!N4 -> 0.070077422 | K29: ='SK Finance'!I4 -> 0.0888 | L29: ='SK Finance'!J4 -> 0.0848 | M29: ='SK Finance'!K4 -> 0.0871 | N29: 0.067265468 | O29: 0.068574962 | P29: ='Shriram Finance'!N4 -> 0.087440192 | Q29: ='Shriram Finance'!O4 -> 0.096064836 | R29: ='Shriram Finance'!P4 -> 0.093419747 | S29: ='Shriram Finance'!Q4 -> 0.089707426 | T29: ='Indostar Capital '!J4 -> 0.060310267 | U29: ='Indostar Capital '!K4 -> 0.049023681 | V29: ='Indostar Capital '!L4 -> 0.059875018 | W29: ='Indostar Capital '!M4 -> 0.083760265
B30: Capitalization
B31: Leverage (Debt/TNW) | C31: ='IKF Finance'!J7 -> 3.1242331 | D31: ='IKF Finance'!K7 -> 3.3533742 | E31: ='IKF Finance'!L7 -> 4.2044968 | F31: ='IKF Finance'!M7 -> 2.8367225 | G31: ='Cholamandalam Inv & Fin'!K6 -> 7.1391068 | H31: ='Cholamandalam Inv & Fin'!L6 -> 7.1274712 | I31: ='Cholamandalam Inv & Fin'!M6 -> 7.7281999 | J31: ='Cholamandalam Inv & Fin'!N6 -> 7.2207307 | K31: ='SK Finance'!I6 -> 2.91 | L31: ='SK Finance'!J6 -> 3.34 | M31: ='SK Finance'!K6 -> 3.24 | N31: 4.9237105 | O31: 4.4152349 | P31: ='Shriram Finance'!N6 -> 3.6462374 | Q31: ='Shriram Finance'!O6 -> 3.8263805 | R31: ='Shriram Finance'!P6 -> 4.6248767 | S31: ='Shriram Finance'!Q6 -> 4.1849923 | T31: ='Indostar Capital '!J6 -> 2.21593 | U31: ='Indostar Capital '!K6 -> 2.6647577 | V31: ='Indostar Capital '!L6 -> 2.4664765 | W31: ='Indostar Capital '!M6 -> 1.7353725
B32: CAR | C32: ='IKF Finance'!J8 -> 0.3302 | D32: ='IKF Finance'!K8 -> 0.265 | E32: ='IKF Finance'!L8 -> 0.2086 | F32: ='IKF Finance'!M8 -> 0.2734 | G32: ='Cholamandalam Inv & Fin'!K7 -> 0.1713 | H32: ='Cholamandalam Inv & Fin'!L7 -> 0.1857 | I32: ='Cholamandalam Inv & Fin'!M7 -> 0.198 | J32: ='Cholamandalam Inv & Fin'!N7 -> 0.192 | K32: ='SK Finance'!I7 -> 0.3386 | L32: ='SK Finance'!J7 -> 0.2951 | M32: ='SK Finance'!K7 -> 0.2541 | N32: 0.225 | O32: 0.2297 | P32: ='Shriram Finance'!N7 -> 0.2261 | Q32: ='Shriram Finance'!O7 -> 0.203 | R32: ='Shriram Finance'!P7 -> 0.2066 | S32: ='Shriram Finance'!Q7 -> 0.204 | T32: ='Indostar Capital '!J7 -> 0.315 | U32: ='Indostar Capital '!K7 -> 0.289 | V32: ='Indostar Capital '!L7 -> 0.285 | W32: ='Indostar Capital '!M7 -> 0.361
B33: TNW/Loan Book | C33: ='IKF Finance'!J9 -> 0.30510061 | D33: ='IKF Finance'!K9 -> 0.24764509 | E33: ='IKF Finance'!L9 -> 0.20419764 | F33: ='IKF Finance'!M9 -> 0.28469266 | G33: ='Cholamandalam Inv & Fin'!K8 -> 0.13018864 | H33: ='Cholamandalam Inv & Fin'!L8 -> 0.13063618 | I33: ='Cholamandalam Inv & Fin'!M8 -> 0.12449294 | J33: ='Cholamandalam Inv & Fin'!N8 -> 0.13422285 | K33: ='SK Finance'!I8 -> 0.31334635 | L33: ='SK Finance'!J8 -> 0.2881398 | M33: ='SK Finance'!K8 -> 0.27928501 | N33: 0.18562763 | O33: 0.20630382 | P33: ='Shriram Finance'!N8 -> 0.23621148 | Q33: ='Shriram Finance'!O8 -> 0.23358115 | R33: ='Shriram Finance'!P8 -> 0.19505533 | S33: ='Shriram Finance'!Q8 -> 0.19957631 | T33: ='Indostar Capital '!J8 -> 0.37859508 | U33: ='Indostar Capital '!K8 -> 0.36043188 | V33: ='Indostar Capital '!L8 -> 0.37566988 | W33: ='Indostar Capital '!M8 -> 0.40203302
B34: Operational Efficiency
B35: Cost to Income (on total operating income net-off interest expenses) | C35: ='IKF Finance'!J11 -> 0.45112782 | D35: ='IKF Finance'!K11 -> 0.47317073 | E35: ='IKF Finance'!L11 -> 0.49146758 | F35: ='IKF Finance'!M11 -> 0.41704036 | G35: ='Cholamandalam Inv & Fin'!K10 -> 0.39674611 | H35: ='Cholamandalam Inv & Fin'!L10 -> 0.42454498 | I35: ='Cholamandalam Inv & Fin'!M10 -> 0.40263952 | J35: ='Cholamandalam Inv & Fin'!N10 -> 0.39583333 | K35: ='SK Finance'!I10 -> 0.50943678 | L35: ='SK Finance'!J10 -> 0.48898365 | M35: ='SK Finance'!K10 -> 0.47859238 | N35: 0.23735177 | O35: 0.22369933 | P35: ='Shriram Finance'!N10 -> 0.28520585 | Q35: ='Shriram Finance'!O10 -> 0.29712391 | R35: ='Shriram Finance'!P10 -> 0.3055306 | S35: ='Shriram Finance'!Q10 -> 0.30178961 | T35: ='Indostar Capital '!J10 -> 0.72727273 | U35: ='Indostar Capital '!K10 -> 0.74378585 | V35: ='Indostar Capital '!L10 -> 0.7254902 | W35: ='Indostar Capital '!M10 -> 0.65560686
B36: Cost to Income (on total operating income) | C36: ='IKF Finance'!J12 -> 0.20905923 | D36: ='IKF Finance'!K12 -> 0.22823529 | E36: ='IKF Finance'!L12 -> 0.2304 | F36: ='IKF Finance'!M12 -> 0.21552723 | G36: ='Cholamandalam Inv & Fin'!K11 -> 0.21793666 | H36: ='Cholamandalam Inv & Fin'!L11 -> 0.21659769 | I36: ='Cholamandalam Inv & Fin'!M11 -> 0.20738007 | J36: ='Cholamandalam Inv & Fin'!N11 -> 0.21218772 | K36: ='SK Finance'!I11 -> 0.29695812 | L36: ='SK Finance'!J11 -> 0.28931876 | M36: ='SK Finance'!K11 -> 0.28895184 | N36: 0.11398844 | O36: 0.11060977 | P36: ='Shriram Finance'!N11 -> 0.16502229 | Q36: ='Shriram Finance'!O11 -> 0.17130305 | R36: ='Shriram Finance'!P11 -> 0.17074628 | S36: ='Shriram Finance'!Q11 -> 0.16681907 | T36: ='Indostar Capital '!J11 -> 0.33849329 | U36: ='Indostar Capital '!K11 -> 0.35235507 | V36: ='Indostar Capital '!L11 -> 0.34259259 | W36: ='Indostar Capital '!M11 -> 0.36323901
B37: Operating Expenses: Avg. Assets | C37: ='IKF Finance'!J13 -> 0.02170767 | D37: ='IKF Finance'!K13 -> 0.026387378 | E37: ='IKF Finance'!L13 -> 0.028731045 | F37: ='IKF Finance'!M13 -> 0.027527009 | G37: ='Cholamandalam Inv & Fin'!K12 -> 0.02448994 | H37: ='Cholamandalam Inv & Fin'!L12 -> 0.030240733 | I37: ='Cholamandalam Inv & Fin'!M12 -> 0.02981857 | J37: ='Cholamandalam Inv & Fin'!N12 -> 0.029432438 | K37: ='SK Finance'!I12 -> 0.043207955 | L37: ='SK Finance'!J12 -> 0.049624709 | M37: ='SK Finance'!K12 -> 0.050105922 | N37: 0.016283818 | O37: 0.015668004 | P37: ='Shriram Finance'!N12 -> 0.025467037 | Q37: ='Shriram Finance'!O12 -> 0.027167015 | R37: ='Shriram Finance'!P12 -> 0.026899699 | S37: ='Shriram Finance'!Q12 -> 0.026105636 | T37: ='Indostar Capital '!J12 -> 0.040299791 | U37: ='Indostar Capital '!K12 -> 0.04142705 | V37: ='Indostar Capital '!L12 -> 0.044694295 | W37: ='Indostar Capital '!M12 -> 0.053194124
B38: Loan Book Performance
B39: Gross NPA % | C39: ='IKF Finance'!J15 -> 0.028544689 | D39: ='IKF Finance'!K15 -> 0.023397144 | E39: ='IKF Finance'!L15 -> 0.022518583 | F39: ='IKF Finance'!M15 -> 0.025200068 | G39: ='Cholamandalam Inv & Fin'!K14 -> 0.047284912 | H39: ='Cholamandalam Inv & Fin'!L14 -> 0.036039716 | I39: ='Cholamandalam Inv & Fin'!M14 -> 0.028653878 | J39: ='Cholamandalam Inv & Fin'!N14 -> 0.031102491 | K39: ='SK Finance'!I14 -> 0.034984544 | L39: ='SK Finance'!J14 -> 0.047457346 | M39: ='SK Finance'!K14 -> 0.043379963 | N39: 0.071371861 | O39: 0.070705001 | P39: ='Shriram Finance'!N14 -> 0.062082896 | Q39: ='Shriram Finance'!O14 -> 0.058101449 | R39: ='Shriram Finance'!P14 -> 0.045549331 | S39: ='Shriram Finance'!Q14 -> 0.045777041 | T39: ='Indostar Capital '!J14 -> 0.080529894 | U39: ='Indostar Capital '!K14 -> 0.049698317 | V39: ='Indostar Capital '!L14 -> 0.045150054 | W39: ='Indostar Capital '!M14 -> 0.047731077
B40: Net NPA% | C40: ='IKF Finance'!J16 -> 0.022461394 | D40: ='IKF Finance'!K16 -> 0.017927682 | E40: ='IKF Finance'!L16 -> 0.014866638 | F40: ='IKF Finance'!M16 -> 0.016686532 | G40: ='Cholamandalam Inv & Fin'!K15 -> 0.031322794 | H40: ='Cholamandalam Inv & Fin'!L15 -> 0.023361768 | I40: ='Cholamandalam Inv & Fin'!M15 -> 0.015681856 | J40: ='Cholamandalam Inv & Fin'!N15 -> 0.016394648 | K40: ='SK Finance'!I15 -> 0.024409039 | L40: ='SK Finance'!J15 -> 0.033708796 | M40: ='SK Finance'!K15 -> 0.028331214 | N40: 0.041368571 | O40: 0.035370599 | P40: ='Shriram Finance'!N15 -> 0.030953196 | Q40: ='Shriram Finance'!O15 -> 0.028009506 | R40: ='Shriram Finance'!P15 -> 0.025831422 | S40: ='Shriram Finance'!Q15 -> 0.022733632 | T40: ='Indostar Capital '!J15 -> 0.036081576 | U40: ='Indostar Capital '!K15 -> 0.020323912 | V40: ='Indostar Capital '!L15 -> 0.024115756 | W40: ='Indostar Capital '!M15 -> 0.020332565
B41: Provision coverage Ratio | C41: ='IKF Finance'!J17 -> 0.21311475 | D41: ='IKF Finance'!K17 -> 0.23376623 | E41: ='IKF Finance'!L17 -> 0.33980583 | F41: ='IKF Finance'!M17 -> 0.33783784 | G41: =(G39-G40)/G39 -> 0.33757319 | H41: =(H39-H40)/H39 -> 0.35177714 | I41: =(I39-I40)/I39 -> 0.45271437 | J41: =(J39-J40)/J39 -> 0.47288311 | K41: ='SK Finance'!I16 -> 0.30229079 | L41: ='SK Finance'!J16 -> 0.28970332 | M41: ='SK Finance'!K16 -> 0.34690554 | N41: 0.42037982 | O41: 0.49974402 | P41: ='Shriram Finance'!N16 -> 0.50142152 | Q41: ='Shriram Finance'!O16 -> 0.5179207 | R41: ='Shriram Finance'!P16 -> 0.43289129 | S41: ='Shriram Finance'!Q16 -> 0.50338354 | T41: ='Indostar Capital '!J16 -> 0.55194805 | U41: ='Indostar Capital '!K16 -> 0.59105431 | V41: ='Indostar Capital '!L16 -> 0.46587537 | W41: ='Indostar Capital '!M16 -> 0.57401831
B42: 31-60 | C42: NA | D42: 0.038 | E42: 0.0348 | F42: 0.0176 | G42: NA | H42: NA | I42: NA | J42: NA | K42: NA | L42: NA | M42: 0.074 | N42: NA | O42: NA | P42: NA | Q42: NA | R42: NA | S42: NA | T42: NA | U42: NA | V42: 0.06
...

Sheet NBFC-Educational Loans
C2: NBFC - Educational Loans
C3: Avanse Financial | F3: Auxilo Finserve | I3: HDFC Credila | L3: EdGro Finance
C4: FY 24 | D4: FY 25 | E4: FY 26 | F4: FY 24 | G4: FY 25 | H4: FY 26 | I4: FY 24 | J4: FY 25 | K4: FY 26 | L4: FY 24 | M4: FY 25 | N4: FY 26
B5: Particulars | C5: Aud | D5: Aud | E5: Aud | F5: Aud | G5: Aud | H5: Aud | I5: Aud | J5: Aud | K5: Aud | L5: Aud | M5: Aud | N5: Aud
C6: Rs in Crores | F6: Rs in Crores | I6: Rs in Crores | L6: Rs in Crores
B7: Revenue from operations | C7: ='Avanse Financial'!C6 -> 1726.2 | D7: ='Avanse Financial'!D6 -> 2013 | E7: ='Avanse Financial'!E6 -> 2882 | F7: ='Auxilo Finserve '!C6 -> 356.7 | G7: ='Auxilo Finserve '!D6 -> 528.1 | H7: ='Auxilo Finserve '!E6 -> 675.8 | I7: ='Hdfc Credila'!C6 -> 2771.04 | J7: ='Hdfc Credila'!D6 -> 4726 | K7: ='Hdfc Credila'!E6 -> 6061.49 | L7: ='EdGro Finance'!C6 -> 4 | M7: ='EdGro Finance'!D6 -> 48 | N7: ='EdGro Finance'!E6 -> 102
B8: Interest Income | C8: ='Avanse Financial'!C7 -> 1386.4 | D8: ='Avanse Financial'!D7 -> 1963.7 | E8: ='Avanse Financial'!E7 -> 2462.4 | F8: ='Auxilo Finserve '!C7 -> 312.1 | G8: ='Auxilo Finserve '!D7 -> 463.9 | H8: ='Auxilo Finserve '!E7 -> 596.3 | I8: ='Hdfc Credila'!C7 -> 2535.35 | J8: ='Hdfc Credila'!D7 -> 4165.57 | K8: ='Hdfc Credila'!E7 -> 5690.4 | L8: ='EdGro Finance'!C7 -> 3 | M8: ='EdGro Finance'!D7 -> 32 | N8: ='EdGro Finance'!E7 -> 74
B9: Other Operation Income | C9: ='Avanse Financial'!C9 -> 339.7 | D9: ='Avanse Financial'!D9 -> 49.3 | E9: ='Avanse Financial'!E9 -> 419.6 | F9: ='Auxilo Finserve '!C9 -> 44.6 | G9: ='Auxilo Finserve '!D9 -> 64.2 | H9: ='Auxilo Finserve '!E9 -> 79.5 | I9: ='Hdfc Credila'!C9 -> 235.69 | J9: ='Hdfc Credila'!D9 -> 560.43 | K9: ='Hdfc Credila'!E9 -> 371.09 | L9: ='EdGro Finance'!C9 -> 1 | M9: ='EdGro Finance'!D9 -> 16 | N9: ='EdGro Finance'!E9 -> 19
B10: Interest expended | C10: ='Avanse Financial'!C10 -> 875.6 | D10: ='Avanse Financial'!D10 -> 1217 | E10: ='Avanse Financial'!E10 -> 1530 | F10: ='Auxilo Finserve '!C10 -> 195.3 | G10: ='Auxilo Finserve '!D10 -> 282.2 | H10: ='Auxilo Finserve '!E10 -> 384.7 | I10: ='Hdfc Credila'!C10 -> 1731.02 | J10: ='Hdfc Credila'!D10 -> 2893.44 | K10: ='Hdfc Credila'!E10 -> 3639.34 | L10: ='EdGro Finance'!C10 -> 3 | M10: ='EdGro Finance'!D10 -> 24 | N10: ='EdGro Finance'!E10 -> 34
B11: Net Interest Income | C11: ='Avanse Financial'!C11 -> 510.8 | D11: ='Avanse Financial'!D11 -> 746.7 | E11: ='Avanse Financial'!E11 -> 932.4 | F11: ='Auxilo Finserve '!C11 -> 116.9 | G11: ='Auxilo Finserve '!D11 -> 181.7 | H11: ='Auxilo Finserve '!E11 -> 211.6 | I11: ='Hdfc Credila'!C11 -> 804.33 | J11: ='Hdfc Credila'!D11 -> 1272.13 | K11: ='Hdfc Credila'!E11 -> 2051.06 | L11: ='EdGro Finance'!C11 -> 0 | M11: ='EdGro Finance'!D11 -> 8 | N11: ='EdGro Finance'!E11 -> 40
B12: Total Operating Income | C12: ='Avanse Financial'!C12 -> 1726.1 | D12: ='Avanse Financial'!D12 -> 2013 | E12: ='Avanse Financial'!E12 -> 2882 | F12: ='Auxilo Finserve '!C12 -> 356.7 | G12: ='Auxilo Finserve '!D12 -> 528.1 | H12: ='Auxilo Finserve '!E12 -> 675.8 | I12: ='Hdfc Credila'!C12 -> 2771.04 | J12: ='Hdfc Credila'!D12 -> 4726 | K12: ='Hdfc Credila'!E12 -> 6061.49 | L12: ='EdGro Finance'!C12 -> 4 | M12: ='EdGro Finance'!D12 -> 48 | N12: ='EdGro Finance'!E12 -> 93
B13: Other income | C13: ='Avanse Financial'!C13 -> 2.1 | D13: ='Avanse Financial'!D13 -> 337.8 | E13: ='Avanse Financial'!E13 -> 6.9 | F13: ='Auxilo Finserve '!C13 -> 10.6 | G13: ='Auxilo Finserve '!D13 -> 15.5 | H13: ='Auxilo Finserve '!E13 -> 13.9 | I13: ='Hdfc Credila'!C13 -> 0 | J13: ='Hdfc Credila'!D13 -> 0 | K13: ='Hdfc Credila'!E13 -> 5.54 | L13: ='EdGro Finance'!C13 -> 3 | M13: ='EdGro Finance'!D13 -> 3 | N13: ='EdGro Finance'!E13 -> 9
B14: Total Income | C14: ='Avanse Financial'!C14 -> 1728.3 | D14: ='Avanse Financial'!D14 -> 2350.8 | E14: ='Avanse Financial'!E14 -> 2888.9 | F14: ='Auxilo Finserve '!C14 -> 367.3 | G14: ='Auxilo Finserve '!D14 -> 543.6 | H14: ='Auxilo Finserve '!E14 -> 689.7 | I14: ='Hdfc Credila'!C14 -> 2771.04 | J14: ='Hdfc Credila'!D14 -> 4726 | K14: ='Hdfc Credila'!E14 -> 6067.03 | L14: ='EdGro Finance'!C14 -> 7 | M14: ='EdGro Finance'!D14 -> 51 | N14: ='EdGro Finance'!E14 -> 102
B15: Operating expenses | C15: ='Avanse Financial'!C15 -> 313.4 | D15: ='Avanse Financial'!D15 -> 394.2 | E15: ='Avanse Financial'!E15 -> 438.1 | F15: ='Auxilo Finserve '!C15 -> 72.6 | G15: ='Auxilo Finserve '!D15 -> 98.5 | H15: ='Auxilo Finserve '!E15 -> 135.6 | I15: ='Hdfc Credila'!C15 -> 281.87 | J15: ='Hdfc Credila'!D15 -> 360.04 | K15: ='Hdfc Credila'!E15 -> 498.13 | L15: ='EdGro Finance'!C15 -> 4 | M15: ='EdGro Finance'!D15 -> 21 | N15: ='EdGro Finance'!E15 -> 54
B16: Operating profit | C16: ='Avanse Financial'!C16 -> 1412.7 | D16: ='Avanse Financial'!D16 -> 1618.8 | E16: ='Avanse Financial'!E16 -> 2443.9 | F16: ='Auxilo Finserve '!C16 -> 284.1 | G16: ='Auxilo Finserve '!D16 -> 429.6 | H16: ='Auxilo Finserve '!E16 -> 540.2 | I16: ='Hdfc Credila'!C16 -> 2489.17 | J16: ='Hdfc Credila'!D16 -> 4365.96 | K16: ='Hdfc Credila'!E16 -> 5563.36 | L16: ='EdGro Finance'!C16 -> 0 | M16: ='EdGro Finance'!D16 -> 27 | N16: ='EdGro Finance'!E16 -> 39
B17: Pre-Provisioning Operating Profit | C17: ='Avanse Financial'!C17 -> 539.3 | D17: ='Avanse Financial'!D17 -> 739.6 | E17: ='Avanse Financial'!E17 -> 920.8 | F17: ='Auxilo Finserve '!C17 -> 99.4 | G17: ='Auxilo Finserve '!D17 -> 162.9 | H17: ='Auxilo Finserve '!E17 -> 169.4 | I17: ='Hdfc Credila'!C17 -> 758.15 | J17: ='Hdfc Credila'!D17 -> 1472.52 | K17: ='Hdfc Credila'!E17 -> 1929.56 | L17: ='EdGro Finance'!C17 -> -3 | M17: ='EdGro Finance'!D17 -> 3 | N17: ='EdGro Finance'!E17 -> 5
B18: Provisions | C18: ='Avanse Financial'!C18 -> 79.6 | D18: ='Avanse Financial'!D18 -> 64.7 | E18: ='Avanse Financial'!E18 -> 116.3 | F18: ='Auxilo Finserve '!C18 -> 6.8 | G18: ='Auxilo Finserve '!D18 -> 12.9 | H18: ='Auxilo Finserve '!E18 -> 12.7 | I18: ='Hdfc Credila'!C18 -> 49.79 | J18: ='Hdfc Credila'!D18 -> 146.54 | K18: ='Hdfc Credila'!E18 -> 173.33 | L18: ='EdGro Finance'!C18 -> 1 | M18: ='EdGro Finance'!D18 -> 3 | N18: ='EdGro Finance'!E18 -> 8
B19: PAT | C19: ='Avanse Financial'!C19 -> 342.6 | D19: ='Avanse Financial'!D19 -> 504.2 | E19: ='Avanse Financial'!E19 -> 597.9 | F19: ='Auxilo Finserve '!C19 -> 69.2 | G19: ='Auxilo Finserve '!D19 -> 111.9 | H19: ='Auxilo Finserve '!E19 -> 116.9 | I19: ='Hdfc Credila'!C19 -> 528.84 | J19: ='Hdfc Credila'!D19 -> 989.96 | K19: ='Hdfc Credila'!E19 -> 1316.3 | L19: ='EdGro Finance'!C19 -> 0.31 | M19: ='EdGro Finance'!D19 -> 2 | N19: ='EdGro Finance'!E19 -> 5
B20: TNW | C20: ='Avanse Financial'!C20 -> 3600.5 | D20: ='Avanse Financial'!D20 -> 4065 | E20: ='Avanse Financial'!E20 -> 5999.4 | F20: ='Auxilo Finserve '!C20 -> 982.6 | G20: ='Auxilo Finserve '!D20 -> 1387.5 | H20: ='Auxilo Finserve '!E20 -> 1505 | I20: ='Hdfc Credila'!C20 -> 4981.23 | J20: ='Hdfc Credila'!D20 -> 8619.57 | K20: ='Hdfc Credila'!E20 -> 9923.31 | L20: ='EdGro Finance'!C20 -> 107 | M20: ='EdGro Finance'!D20 -> 113 | N20: ='EdGro Finance'!E20 -> 351
B21: Total Debt | C21: ='Avanse Financial'!C22 -> 10135.2 | D21: ='Avanse Financial'!D22 -> 14473.6 | E21: ='Avanse Financial'!E22 -> 18471.4 | F21: ='Auxilo Finserve '!C22 -> 2345.2 | G21: ='Auxilo Finserve '!D22 -> 3417.8 | H21: ='Auxilo Finserve '!E22 -> 3931.4 | I21: ='Hdfc Credila'!C22 -> 26032.83 | J21: ='Hdfc Credila'!D22 -> 38869.01 | K21: ='Hdfc Credila'!E22 -> 45866.02 | L21: ='EdGro Finance'!C22 -> 156 | M21: ='EdGro Finance'!D22 -> 221 | N21: ='EdGro Finance'!E22 -> 450
B22: Total Assets | C22: ='Avanse Financial'!C23 -> 14267.6 | D22: ='Avanse Financial'!D23 -> 18931.9 | E22: ='Avanse Financial'!E23 -> 25114.3 | F22: ='Auxilo Finserve '!C23 -> 3363.6 | G22: ='Auxilo Finserve '!D23 -> 4858.9 | H22: ='Auxilo Finserve '!E23 -> 5489.1 | I22: ='Hdfc Credila'!C23 -> 31503.84 | J22: ='Hdfc Credila'!D23 -> 48119.57 | K22: ='Hdfc Credila'!E23 -> 57272.75 | L22: ='EdGro Finance'!C23 -> 271 | M22: ='EdGro Finance'!D23 -> 354 | N22: ='EdGro Finance'!E23 -> 830
B23: Loans & Advances (Gross) | C23: ='Avanse Financial'!C24 -> 12520.7 | D23: ='Avanse Financial'!D24 -> 17419.9 | E23: ='Avanse Financial'!E24 -> 20600.5 | F23: ='Auxilo Finserve '!C24 -> 2859.4 | G23: ='Auxilo Finserve '!D24 -> 4298.5 | H23: ='Auxilo Finserve '!E24 -> 4936.7 | I23: ='Hdfc Credila'!C24 -> 28187.2 | J23: ='Hdfc Credila'!D24 -> 41709.64 | K23: ='Hdfc Credila'!E24 -> 50653.56 | L23: ='EdGro Finance'!C24 -> 153 | M23: ='EdGro Finance'!D24 -> 279 | N23: ='EdGro Finance'!E24 -> 608
B24: Gross NPAs | C24: ='Avanse Financial'!C25 -> 53.1 | D24: ='Avanse Financial'!D25 -> 44.5 | E24: ='Avanse Financial'!E25 -> 75 | F24: ='Auxilo Finserve '!C25 -> 25 | G24: ='Auxilo Finserve '!D25 -> 22.6 | H24: ='Auxilo Finserve '!E25 -> 18 | I24: ='Hdfc Credila'!C25 -> 21.46 | J24: ='Hdfc Credila'!D25 -> 79.88 | K24: ='Hdfc Credila'!E25 -> 131.7 | L24: ='EdGro Finance'!C25 -> 0 | M24: ='EdGro Finance'!D25 -> 3 | N24: ='EdGro Finance'!E25 -> 0
B25: Net NPAs | C25: ='Avanse Financial'!C26 -> 16 | D25: ='Avanse Financial'!D26 -> 6.8 | E25: ='Avanse Financial'!E26 -> 12.2 | F25: ='Auxilo Finserve '!C26 -> 14.4 | G25: ='Auxilo Finserve '!D26 -> 3.5 | H25: ='Auxilo Finserve '!E26 -> 5 | I25: ='Hdfc Credila'!C26 -> 9.79 | J25: ='Hdfc Credila'!D26 -> 27.95 | K25: ='Hdfc Credila'!E26 -> 50.65 | L25: ='EdGro Finance'!C26 -> 0 | M25: ='EdGro Finance'!D26 -> 1 | N25: ='EdGro Finance'!E26 -> 0
C27: ='Avanse Financial'!H3 -> FY24(A) | D27: ='Avanse Financial'!I3 -> FY25(A) | E27: ='Avanse Financial'!J3 -> FY26(A) | F27: ='Auxilo Finserve '!H3 -> FY24(A) | G27: ='Auxilo Finserve '!I3 -> FY25(A) | H27: ='Auxilo Finserve '!J3 -> FY26(A) | I27: ='Hdfc Credila'!H3 -> FY24 (A) | J27: ='Hdfc Credila'!I3 -> FY25 (A) | K27: ='Hdfc Credila'!J3 -> FY26 (A) | L27: ='EdGro Finance'!H3 -> FY24 (A) | M27: ='EdGro Finance'!I3 -> FY25 (A) | N27: ='EdGro Finance'!J3 -> FY26 (A)
B28: Profitability
B29: Net Interest Margin | C29: ='Avanse Financial'!H5 -> 0.0487 | D29: ='Avanse Financial'!I5 -> 0.04987876 | E29: ='Avanse Financial'!J5 -> 0.049047354 | F29: ='Auxilo Finserve '!H5 -> 0.051150961 | G29: ='Auxilo Finserve '!I5 -> 0.05076908 | H29: ='Auxilo Finserve '!J5 -> 0.045824671 | I29: ='Hdfc Credila'!H5 -> 0.037 | J29: ='Hdfc Credila'!I5 -> 0.036400215 | K29: ='Hdfc Credila'!J5 -> 0.044412926 | L29: ='EdGro Finance'!H5 -> - | M29: ='EdGro Finance'!I5 -> 0.037037037 | N29: ='EdGro Finance'!J5 -> 0.090191657
B30: Capitalization
B31: Leverage (Debt/TNW) | C31: ='Avanse Financial'!H7 -> 2.8149424 | D31: ='Avanse Financial'!I7 -> 3.5605412 | E31: ='Avanse Financial'!J7 -> 3.0788746 | F31: ='Auxilo Finserve '!H7 -> 2.3867291 | G31: ='Auxilo Finserve '!I7 -> 2.4632793 | H31: ='Auxilo Finserve '!J7 -> 2.6122259 | I31: ='Hdfc Credila'!H7 -> 5.2261851 | J31: ='Hdfc Credila'!I7 -> 4.5093908 | K31: ='Hdfc Credila'!J7 -> 4.6220485 | L31: ='EdGro Finance'!H7 -> 1.4579439 | M31: ='EdGro Finance'!I7 -> 1.9557522 | N31: ='EdGro Finance'!J7 -> 1.2820513
B32: CAR | C32: ='Avanse Financial'!H8 -> 0.2752 | D32: ='Avanse Financial'!I8 -> 0.2244 | E32: ='Avanse Financial'!J8 -> 0.2673 | F32: ='Auxilo Finserve '!H8 -> 0.3149 | G32: ='Auxilo Finserve '!I8 -> 0.3 | H32: ='Auxilo Finserve '!J8 -> 0.321 | I32: ='Hdfc Credila'!H8 -> 0.2045 | J32: ='Hdfc Credila'!I8 -> 0.2181 | K32: ='Hdfc Credila'!J8 -> 0.1989 | L32: ='EdGro Finance'!H8 -> 0.4737 | M32: ='EdGro Finance'!I8 -> 0.3398 | N32: ='EdGro Finance'!J8 -> 0.4502
B33: TNW/Loan Book | C33: ='Avanse Financial'!H9 -> 0.28756379 | D33: ='Avanse Financial'!I9 -> 0.23335381 | E33: ='Avanse Financial'!J9 -> 0.29122594 | F33: ='Auxilo Finserve '!H9 -> 0.34363853 | G33: ='Auxilo Finserve '!I9 -> 0.32278702 | H33: ='Auxilo Finserve '!J9 -> 0.30485952 | I33: ='Hdfc Credila'!H9 -> 0.17671957 | J33: ='Hdfc Credila'!I9 -> 0.20665654 | K33: ='Hdfc Credila'!J9 -> 0.19590548 | L33: ='EdGro Finance'!H9 -> 0.69934641 | M33: ='EdGro Finance'!I9 -> 0.40501792 | N33: ='EdGro Finance'!J9 -> 0.57730263
B34: Operational Efficiency
B35: Cost to Income (on total operating income net-off interest expenses) | C35: ='Avanse Financial'!H11 -> 0.36848912 | D35: ='Avanse Financial'!I11 -> 0.49522613 | E35: ='Avanse Financial'!J11 -> 0.32403846 | F35: ='Auxilo Finserve '!H11 -> 0.44981413 | G35: ='Auxilo Finserve '!I11 -> 0.40056934 | H35: ='Auxilo Finserve '!J11 -> 0.46581931 | I35: ='Hdfc Credila'!H11 -> 0.27102363 | J35: ='Hdfc Credila'!I11 -> 0.19646833 | K35: ='Hdfc Credila'!J11 -> 0.20565613 | L35: ='EdGro Finance'!H11 -> 4 | M35: ='EdGro Finance'!I11 -> 0.875 | N35: ='EdGro Finance'!J11 -> 0.91525424
B36: Cost to Income (on total operating income) | C36: ='Avanse Financial'!H12 -> 0.18156538 | D36: ='Avanse Financial'!I12 -> 0.19582712 | E36: ='Avanse Financial'!J12 -> 0.15201249 | F36: ='Auxilo Finserve '!H12 -> 0.20353238 | G36: ='Auxilo Finserve '!I12 -> 0.1865177 | H36: ='Auxilo Finserve '!J12 -> 0.20065108 | I36: ='Hdfc Credila'!H12 -> 0.10171993 | J36: ='Hdfc Credila'!I12 -> 0.076182818 | K36: ='Hdfc Credila'!J12 -> 0.082179464 | L36: ='EdGro Finance'!H12 -> 1 | M36: ='EdGro Finance'!I12 -> 0.4375 | N36: ='EdGro Finance'!J12 -> 0.58064516
B37: Operating Expenses: Avg. Assets | C37: ='Avanse Financial'!H13 -> 0.026 | D37: ='Avanse Financial'!I13 -> 0.023747346 | E37: ='Avanse Financial'!J13 -> 0.019892749 | F37: ='Auxilo Finserve '!H13 -> 0.027262572 | G37: ='Auxilo Finserve '!I13 -> 0.02395865 | H37: ='Auxilo Finserve '!J13 -> 0.026207963 | I37: ='Hdfc Credila'!H13 -> 0.011767422 | J37: ='Hdfc Credila'!I13 -> 0.0090435715 | K37: ='Hdfc Credila'!J13 -> 0.0094528709 | L37: ='EdGro Finance'!H13 -> 0.026143791 | M37: ='EdGro Finance'!I13 -> 0.0672 | N37: ='EdGro Finance'!J13 -> 0.091216216
B38: Loan Book Performance
B39: Gross NPA % | C39: ='Avanse Financial'!H15 -> 0.0042409769 | D39: ='Avanse Financial'!I15 -> 0.0025545497 | E39: ='Avanse Financial'!J15 -> 0.0036406883 | F39: ='Auxilo Finserve '!H15 -> 0.008743093 | G39: ='Auxilo Finserve '!I15 -> 0.005257648 | H39: ='Auxilo Finserve '!J15 -> 0.0036461604 | I39: ='Hdfc Credila'!H15 -> 0.00076133848 | J39: ='Hdfc Credila'!I15 -> 0.0019151448 | K39: ='Hdfc Credila'!J15 -> 0.0026000147 | L39: ='EdGro Finance'!H15 -> - | M39: ='EdGro Finance'!I15 -> 0.0095 | N39: ='EdGro Finance'!J15 -> 0.0039
B40: Net NPA% | C40: ='Avanse Financial'!H16 -> 0.0012778838 | D40: ='Avanse Financial'!I16 -> 0.00039035815 | E40: ='Avanse Financial'!J16 -> 0.00059221864 | F40: ='Auxilo Finserve '!H16 -> 0.0050360215 | G40: ='Auxilo Finserve '!I16 -> 0.00081423752 | H40: ='Auxilo Finserve '!J16 -> 0.0010128223 | I40: ='Hdfc Credila'!H16 -> 0.00034732077 | J40: ='Hdfc Credila'!I16 -> 0.00067010888 | K40: ='Hdfc Credila'!J16 -> 0.00099992972 | L40: ='EdGro Finance'!H16 -> - | M40: ='EdGro Finance'!I16 -> 0.0039 | N40: ='EdGro Finance'!J16 -> 0.0029
B41: Provision coverage Ratio | C41: ='Avanse Financial'!H17 -> 0.69868173 | D41: ='Avanse Financial'!I17 -> 0.84719101 | E41: ='Avanse Financial'!J17 -> 0.83733333 | F41: ='Auxilo Finserve '!H17 -> 0.424 | G41: ='Auxilo Finserve '!I17 -> 0.84513274 | H41: ='Auxilo Finserve '!J17 -> 0.72222222 | I41: ='Hdfc Credila'!H17 -> 0.54380242 | J41: ='Hdfc Credila'!I17 -> 0.65010015 | K41: ='Hdfc Credila'!J17 -> 0.61541382 | L41: ='EdGro Finance'!H17 -> - | M41: ='EdGro Finance'!I17 -> 0.58947368 | N41: ='EdGro Finance'!J17 -> 0.25641026
B42: Credit Cost | C42: ='Avanse Financial'!H18 -> 0.0076 | D42: ='Avanse Financial'!I18 -> 0.0043218907 | E42: ='Avanse Financial'!J18 -> 0.0061177684 | F42: ='Auxilo Finserve '!H18 -> 0.0029713043 | G42: ='Auxilo Finserve '!I18 -> 0.0036044091 | H42: ='Auxilo Finserve '!J18 -> 0.0027503465 | I42: ='Hdfc Credila'!H18 -> 0.0022899745 | J42: ='Hdfc Credila'!I18 -> 0.0041930365 | K42: ='Hdfc Credila'!J18 -> 0.0037532264 | L42: ='EdGro Finance'!H18 -> 0.008 | M42: ='EdGro Finance'!I18 -> 0.0136 | N42: ='EdGro Finance'!J18 -> 0.018038331
...

Sheet NBFC-Gold Loan
C2: NBFC - Gold Loan
C3: Manappuram Finance | G3: Muthoot Finance | K3: Muthoot Fincorp | O3: Muthoot MCred (erstwhile Muthootu Mini Financiers) | S3: Kosamattam Finance
B4: Particulars | C4: ='Manappuram Finance'!H3 -> FY23 | D4: ='Manappuram Finance'!I3 -> FY24 | E4: ='Manappuram Finance'!J3 -> FY25 | F4: ='Manappuram Finance'!K3 -> FY26 | G4: FY 23 | H4: FY 24 | I4: FY 25 | J4: FY 26 | K4: FY 23 | L4: FY 24 | M4: FY 25 | N4: FY 26 | O4: FY 23 | P4: FY 24 | Q4: FY 25 | R4: FY 26 | S4: FY 23 | T4: FY 24 | U4: FY 25 | V4: FY 26
C5: ='Manappuram Finance'!H4 -> Aud | D5: ='Manappuram Finance'!I4 -> Aud | E5: ='Manappuram Finance'!J4 -> Aud | F5: ='Manappuram Finance'!K4 -> Aud | G5: Aud | H5: Aud | I5: Aud | J5: Aud | K5: Aud | L5: Aud | M5: Aud | N5: Aud | O5: Aud | P5: Aud | Q5: Aud | R5: Aud | S5: Aud | T5: Aud | U5: Aud | V5: Aud
C6: Rs in Crores | G6: Rs in Crores | K6: Rs in Crores | O6: Rs in Crores | S6: Rs in Crores
B7: Revenue from operations | C7: ='Manappuram Finance'!H6 -> 4827 | D7: ='Manappuram Finance'!I6 -> 5855 | E7: ='Manappuram Finance'!J6 -> 6914 | F7: ='Manappuram Finance'!K6 -> 7653 | G7: ='Muthoot Finance'!I6 -> 10514.849 | H7: ='Muthoot Finance'!J6 -> 12694 | I7: ='Muthoot Finance'!K6 -> 17156 | J7: ='Muthoot Finance'!L6 -> 27600 | K7: ='Muthoot Fincorp'!D6 -> 3469.8253 | L7: ='Muthoot Fincorp'!E6 -> 4011 | M7: ='Muthoot Fincorp'!F6 -> 5540 | N7: ='Muthoot Fincorp'!G6 -> 8364 | O7: ='Muthoot MCred'!D6 -> 544 | P7: ='Muthoot MCred'!E6 -> 672 | Q7: ='Muthoot MCred'!F6 -> 815 | R7: ='Muthoot MCred'!G6 -> 1113 | S7: ='Kosamattam Finance'!D6 -> 765 | T7: ='Kosamattam Finance'!E6 -> 859 | U7: ='Kosamattam Finance'!F6 -> 900 | V7: ='Kosamattam Finance'!G6 -> 1128
B8: Interest Income | C8: ='Manappuram Finance'!H7 -> 4666 | D8: ='Manappuram Finance'!I7 -> 5664 | E8: ='Manappuram Finance'!J7 -> 6694 | F8: ='Manappuram Finance'!K7 -> 7437 | G8: ='Muthoot Finance'!I7 -> 10148.791 | H8: ='Muthoot Finance'!J7 -> 12186 | I8: ='Muthoot Finance'!K7 -> 16525 | J8: ='Muthoot Finance'!L7 -> 27066 | K8: ='Muthoot Fincorp'!D7 -> 3304.8309 | L8: ='Muthoot Fincorp'!E7 -> 3715 | M8: ='Muthoot Fincorp'!F7 -> 4936 | N8: ='Muthoot Fincorp'!G7 -> 7728 | O8: ='Muthoot MCred'!D7 -> 519 | P8: ='Muthoot MCred'!E7 -> 627 | Q8: ='Muthoot MCred'!F7 -> 744 | R8: ='Muthoot MCred'!G7 -> 1046 | S8: ='Kosamattam Finance'!D7 -> 761 | T8: ='Kosamattam Finance'!E7 -> 854 | U8: ='Kosamattam Finance'!F7 -> 894 | V8: ='Kosamattam Finance'!G7 -> 1107
B9: Other Operation Income | C9: ='Manappuram Finance'!H9 -> 161 | D9: ='Manappuram Finance'!I9 -> 191 | E9: ='Manappuram Finance'!J9 -> 214 | F9: ='Manappuram Finance'!K9 -> 206 | G9: ='Muthoot Finance'!I9 -> 366.058 | H9: ='Muthoot Finance'!J9 -> 508 | I9: ='Muthoot Finance'!K9 -> 631 | J9: ='Muthoot Finance'!L9 -> 534 | K9: ='Muthoot Fincorp'!D9 -> 164.9944 | L9: ='Muthoot Fincorp'!E9 -> 177 | M9: ='Muthoot Fincorp'!F9 -> 273 | N9: ='Muthoot Fincorp'!G9 -> 462 | O9: ='Muthoot MCred'!D9 -> 24 | P9: ='Muthoot MCred'!E9 -> 42 | Q9: ='Muthoot MCred'!F9 -> 67 | R9: ='Muthoot MCred'!G9 -> 63 | S9: ='Kosamattam Finance'!D9 -> 4 | T9: ='Kosamattam Finance'!E9 -> 4 | U9: ='Kosamattam Finance'!F9 -> 6 | V9: ='Kosamattam Finance'!G9 -> 21
B10: Interest expended | C10: ='Manappuram Finance'!H10 -> 1498 | D10: ='Manappuram Finance'!I10 -> 1776 | E10: ='Manappuram Finance'!J10 -> 2327 | F10: ='Manappuram Finance'!K10 -> 2953 | G10: ='Muthoot Finance'!I10 -> 3699.14 | H10: ='Muthoot Finance'!J10 -> 4655 | I10: ='Muthoot Finance'!K10 -> 6429 | J10: ='Muthoot Finance'!L10 -> 9941 | K10: ='Muthoot Fincorp'!D10 -> 1571.3255 | L10: ='Muthoot Fincorp'!E10 -> 1805 | M10: ='Muthoot Fincorp'!F10 -> 2313 | N10: ='Muthoot Fincorp'!G10 -> 3069 | O10: ='Muthoot MCred'!D10 -> 283 | P10: ='Muthoot MCred'!E10 -> 345 | Q10: ='Muthoot MCred'!F10 -> 398 | R10: ='Muthoot MCred'!G10 -> 530 | S10: ='Kosamattam Finance'!D10 -> 433 | T10: ='Kosamattam Finance'!E10 -> 512 | U10: ='Kosamattam Finance'!F10 -> 539 | V10: ='Kosamattam Finance'!G10 -> 628
B11: Net Interest Income | C11: ='Manappuram Finance'!H11 -> 3168 | D11: ='Manappuram Finance'!I11 -> 3888 | E11: ='Manappuram Finance'!J11 -> 4367 | F11: ='Manappuram Finance'!K11 -> 4484 | G11: ='Muthoot Finance'!I11 -> 6449.651 | H11: ='Muthoot Finance'!J11 -> 7531 | I11: ='Muthoot Finance'!K11 -> 10097 | J11: ='Muthoot Finance'!L11 -> 17125 | K11: ='Muthoot Fincorp'!D11 -> 1733.5054 | L11: ='Muthoot Fincorp'!E11 -> 1910 | M11: ='Muthoot Fincorp'!F11 -> 2623 | N11: ='Muthoot Fincorp'!G11 -> 4659 | O11: ='Muthoot MCred'!D11 -> 236 | P11: ='Muthoot MCred'!E11 -> 282 | Q11: ='Muthoot MCred'!F11 -> 347 | R11: ='Muthoot MCred'!G11 -> 516 | S11: ='Kosamattam Finance'!D11 -> 328 | T11: ='Kosamattam Finance'!E11 -> 342 | U11: ='Kosamattam Finance'!F11 -> 355 | V11: ='Kosamattam Finance'!G11 -> 479
B12: Total Operating Income | C12: ='Manappuram Finance'!H12 -> 4827 | D12: ='Manappuram Finance'!I12 -> 5855 | E12: ='Manappuram Finance'!J12 -> 6908 | F12: ='Manappuram Finance'!K12 -> 7643 | G12: ='Muthoot Finance'!I12 -> 10514.849 | H12: ='Muthoot Finance'!J12 -> 12694 | I12: ='Muthoot Finance'!K12 -> 17156 | J12: ='Muthoot Finance'!L12 -> 27600 | K12: ='Muthoot Fincorp'!D12 -> 3469.8253 | L12: ='Muthoot Fincorp'!E12 -> 3892 | M12: ='Muthoot Fincorp'!F12 -> 5209 | N12: ='Muthoot Fincorp'!G12 -> 8190 | O12: ='Muthoot MCred'!D12 -> 543 | P12: ='Muthoot MCred'!E12 -> 669 | Q12: ='Muthoot MCred'!F12 -> 811 | R12: ='Muthoot MCred'!G12 -> 1109 | S12: ='Kosamattam Finance'!D12 -> 765 | T12: ='Kosamattam Finance'!E12 -> 858 | U12: ='Kosamattam Finance'!F12 -> 900 | V12: ='Kosamattam Finance'!G12 -> 1128
B13: Other income | C13: ='Manappuram Finance'!H13 -> 0 | D13: ='Manappuram Finance'!I13 -> 0 | E13: ='Manappuram Finance'!J13 -> 6 | F13: ='Manappuram Finance'!K13 -> 11 | G13: ='Muthoot Finance'!I13 -> 28.899 | H13: ='Muthoot Finance'!J13 -> 59 | I13: ='Muthoot Finance'!K13 -> 57 | J13: ='Muthoot Finance'!L13 -> 42 | K13: ='Muthoot Fincorp'!D13 -> 21.4383 | L13: ='Muthoot Fincorp'!E13 -> 119 | M13: ='Muthoot Fincorp'!F13 -> 331 | N13: ='Muthoot Fincorp'!G13 -> 174 | O13: ='Muthoot MCred'!D13 -> 1 | P13: ='Muthoot MCred'!E13 -> 2 | Q13: ='Muthoot MCred'!F13 -> 4 | R13: ='Muthoot MCred'!G13 -> 4 | S13: ='Kosamattam Finance'!D13 -> 0 | T13: ='Kosamattam Finance'!E13 -> 1 | U13: ='Kosamattam Finance'!F13 -> 0 | V13: ='Kosamattam Finance'!G13 -> 0
B14: Total Income | C14: ='Manappuram Finance'!H14 -> 4827 | D14: ='Manappuram Finance'!I14 -> 5855 | E14: ='Manappuram Finance'!J14 -> 6914 | F14: ='Manappuram Finance'!K14 -> 7654 | G14: ='Muthoot Finance'!I14 -> 10543.748 | H14: ='Muthoot Finance'!J14 -> 12753 | I14: ='Muthoot Finance'!K14 -> 17213 | J14: ='Muthoot Finance'!L14 -> 27642 | K14: ='Muthoot Fincorp'!D14 -> 3491.2636 | L14: ='Muthoot Fincorp'!E14 -> 4011 | M14: ='Muthoot Fincorp'!F14 -> 5540 | N14: ='Muthoot Fincorp'!G14 -> 8364 | O14: ='Muthoot MCred'!D14 -> 544 | P14: ='Muthoot MCred'!E14 -> 671 | Q14: ='Muthoot MCred'!F14 -> 815 | R14: ='Muthoot MCred'!G14 -> 1113 | S14: ='Kosamattam Finance'!D14 -> 765 | T14: ='Kosamattam Finance'!E14 -> 859 | U14: ='Kosamattam Finance'!F14 -> 900 | V14: ='Kosamattam Finance'!G14 -> 1128
B15: Operating expenses | C15: ='Manappuram Finance'!H15 -> 1577 | D15: ='Manappuram Finance'!I15 -> 1749 | E15: ='Manappuram Finance'!J15 -> 1949 | F15: ='Manappuram Finance'!K15 -> 2126 | G15: ='Muthoot Finance'!I15 -> 2117.655 | H15: ='Muthoot Finance'!J15 -> 2393 | I15: ='Muthoot Finance'!K15 -> 2890 | J15: ='Muthoot Finance'!L15 -> 3544 | K15: ='Muthoot Fincorp'!D15 -> 1227.437 | L15: ='Muthoot Fincorp'!E15 -> 1396 | M15: ='Muthoot Fincorp'!F15 -> 1971 | N15: ='Muthoot Fincorp'!G15 -> 2853 | O15: ='Muthoot MCred'!D15 -> 181 | P15: ='Muthoot MCred'!E15 -> 209 | Q15: ='Muthoot MCred'!F15 -> 274 | R15: ='Muthoot MCred'!G15 -> 333 | S15: ='Kosamattam Finance'!D15 -> 176 | T15: ='Kosamattam Finance'!E15 -> 183 | U15: ='Kosamattam Finance'!F15 -> 185 | V15: ='Kosamattam Finance'!G15 -> 239
B16: Operating profit | C16: ='Manappuram Finance'!H16 -> 3250 | D16: ='Manappuram Finance'!I16 -> 4106 | E16: ='Manappuram Finance'!J16 -> 4959 | F16: ='Manappuram Finance'!K16 -> 5517 | G16: ='Muthoot Finance'!I16 -> 8397.194 | H16: ='Muthoot Finance'!J16 -> 10301 | I16: ='Muthoot Finance'!K16 -> 14266 | J16: ='Muthoot Finance'!L16 -> 24056 | K16: ='Muthoot Fincorp'!D16 -> 2242.3883 | L16: ='Muthoot Fincorp'!E16 -> 2496 | M16: ='Muthoot Fincorp'!F16 -> 3238 | N16: ='Muthoot Fincorp'!G16 -> 5337 | O16: ='Muthoot MCred'!D16 -> 362 | P16: ='Muthoot MCred'!E16 -> 460 | Q16: ='Muthoot MCred'!F16 -> 537 | R16: ='Muthoot MCred'!G16 -> 776 | S16: ='Kosamattam Finance'!D16 -> 589 | T16: ='Kosamattam Finance'!E16 -> 675 | U16: ='Kosamattam Finance'!F16 -> 715 | V16: ='Kosamattam Finance'!G16 -> 889
B17: Pre-provisioning operating profit | C17: ='Manappuram Finance'!H17 -> 1752 | D17: ='Manappuram Finance'!I17 -> 2330 | E17: ='Manappuram Finance'!J17 -> 2638 | F17: ='Manappuram Finance'!K17 -> 2575 | G17: ='Muthoot Finance'!I17 -> 4726.953 | H17: ='Muthoot Finance'!J17 -> 5705 | I17: ='Muthoot Finance'!K17 -> 7894 | J17: ='Muthoot Finance'!L17 -> 14157 | K17: ='Muthoot Fincorp'!D17 -> 692.5011 | L17: ='Muthoot Fincorp'!E17 -> 810 | M17: ='Muthoot Fincorp'!F17 -> 1256 | N17: ='Muthoot Fincorp'!G17 -> 2442 | O17: ='Muthoot MCred'!D17 -> 80 | P17: ='Muthoot MCred'!E17 -> 117 | Q17: ='Muthoot MCred'!F17 -> 143 | R17: ='Muthoot MCred'!G17 -> 250 | S17: ='Kosamattam Finance'!D17 -> 156 | T17: ='Kosamattam Finance'!E17 -> 163 | U17: ='Kosamattam Finance'!F17 -> 176 | V17: ='Kosamattam Finance'!G17 -> 261
B18: Provisions | C18: ='Manappuram Finance'!H18 -> 45 | D18: ='Manappuram Finance'!I18 -> 108 | E18: ='Manappuram Finance'!J18 -> 263 | F18: ='Manappuram Finance'!K18 -> 535 | G18: ='Muthoot Finance'!I18 -> 60.527 | H18: ='Muthoot Finance'!J18 -> 198 | I18: ='Muthoot Finance'!K18 -> 767 | J18: ='Muthoot Finance'!L18 -> 470 | K18: ='Muthoot Fincorp'!D18 -> 67.1702 | L18: ='Muthoot Fincorp'!E18 -> 30 | M18: ='Muthoot Fincorp'!F18 -> 111 | N18: ='Muthoot Fincorp'!G18 -> 259 | O18: ='Muthoot MCred'!D18 -> -2 | P18: ='Muthoot MCred'!E18 -> 7 | Q18: ='Muthoot MCred'!F18 -> 14 | R18: ='Muthoot MCred'!G18 -> 11 | S18: ='Kosamattam Finance'!D18 -> 28 | T18: ='Kosamattam Finance'!E18 -> 10 | U18: ='Kosamattam Finance'!F18 -> 6 | V18: ='Kosamattam Finance'!G18 -> 11
B19: PAT | C19: ='Manappuram Finance'!H19 -> 1266 | D19: ='Manappuram Finance'!I19 -> 1658 | E19: ='Manappuram Finance'!J19 -> 1783 | F19: ='Manappuram Finance'!K19 -> 1525 | G19: ='Muthoot Finance'!I19 -> 3473.531 | H19: ='Muthoot Finance'!J19 -> 4050 | I19: ='Muthoot Finance'!K19 -> 5201 | J19: ='Muthoot Finance'!L19 -> 10134 | K19: ='Muthoot Fincorp'!D19 -> 459.8108 | L19: ='Muthoot Fincorp'!E19 -> 563 | M19: ='Muthoot Fincorp'!F19 -> 787 | N19: ='Muthoot Fincorp'!G19 -> 1640 | O19: ='Muthoot MCred'!D19 -> 67 | P19: ='Muthoot MCred'!E19 -> 78 | Q19: ='Muthoot MCred'!F19 -> 94 | R19: ='Muthoot MCred'!G19 -> 177 | S19: ='Kosamattam Finance'!D19 -> 107 | T19: ='Kosamattam Finance'!E19 -> 114 | U19: ='Kosamattam Finance'!F19 -> 127 | V19: ='Kosamattam Finance'!G19 -> 185
B20: TNW | C20: ='Manappuram Finance'!H20 -> 8885 | D20: ='Manappuram Finance'!I20 -> 10246 | E20: ='Manappuram Finance'!J20 -> 11682 | F20: ='Manappuram Finance'!K20 -> 15832 | G20: ='Muthoot Finance'!I20 -> 21061.928 | H20: ='Muthoot Finance'!J20 -> 24253 | I20: ='Muthoot Finance'!K20 -> 26724 | J20: ='Muthoot Finance'!L20 -> 34081 | K20: ='Muthoot Fincorp'!D20 -> 3893.0345 | L20: ='Muthoot Fincorp'!E20 -> 4305 | M20: ='Muthoot Fincorp'!F20 -> 4810 | N20: ='Muthoot Fincorp'!G20 -> 6679 | O20: ='Muthoot MCred'!D20 -> 622 | P20: ='Muthoot MCred'!E20 -> 701 | Q20: ='Muthoot MCred'!F20 -> 797 | R20: ='Muthoot MCred'!G20 -> 1159 | S20: ='Kosamattam Finance'!D20 -> 761 | T20: ='Kosamattam Finance'!E20 -> 912 | U20: ='Kosamattam Finance'!F20 -> 1047 | V20: ='Kosamattam Finance'!G20 -> 1067
B21: Total Debt | C21: ='Manappuram Finance'!H22 -> 19229 | D21: ='Manappuram Finance'!I22 -> 22467 | E21: ='Manappuram Finance'!J22 -> 27046 | F21: ='Manappuram Finance'!K22 -> 50611 | G21: ='Muthoot Finance'!I22 -> 49734.307 | H21: ='Muthoot Finance'!J22 -> 58783 | I21: ='Muthoot Finance'!K22 -> 89820 | J21: ='Muthoot Finance'!L22 -> 138443 | K21: ='Muthoot Fincorp'!D22 -> 17823.175 | L21: ='Muthoot Fincorp'!E22 -> 20596 | M21: ='Muthoot Fincorp'!F22 -> 25855 | N21: ='Muthoot Fincorp'!G22 -> 43609 | O21: ='Muthoot MCred'!D22 -> 3207 | P21: ='Muthoot MCred'!E22 -> 3581 | Q21: ='Muthoot MCred'!F22 -> 4119 | R21: ='Muthoot MCred'!G22 -> 6261 | S21: ='Kosamattam Finance'!D22 -> 4659 | T21: ='Kosamattam Finance'!E22 -> 5001 | U21: ='Kosamattam Finance'!F22 -> 5281 | V21: ='Kosamattam Finance'!G22 -> 6925
B22: Total Assets | C22: ='Manappuram Finance'!H23 -> 29338 | D22: ='Manappuram Finance'!I23 -> 33893 | E22: ='Manappuram Finance'!J23 -> 39836 | F22: ='Manappuram Finance'!K23 -> 67554 | G22: ='Muthoot Finance'!I23 -> 72619.814 | H22: ='Muthoot Finance'!J23 -> 85028 | I22: ='Muthoot Finance'!K23 -> 121249 | J22: ='Muthoot Finance'!L23 -> 179945 | K22: ='Muthoot Fincorp'!D23 -> 23699.001 | L22: ='Muthoot Fincorp'!E23 -> 26611 | M22: ='Muthoot Fincorp'!F23 -> 32811 | N22: ='Muthoot Fincorp'!G23 -> 52671 | O22: ='Muthoot MCred'!D23 -> 3858 | P22: ='Muthoot MCred'!E23 -> 4316 | Q22: ='Muthoot MCred'!F23 -> 4960 | R22: ='Muthoot MCred'!G23 -> 7493 | S22: ='Kosamattam Finance'!D23 -> 5444 | T22: ='Kosamattam Finance'!E23 -> 5986 | U22: ='Kosamattam Finance'!F23 -> 6406 | V22: ='Kosamattam Finance'!G23 -> 8285
B23: Loans & Advances (Gross) | C23: ='Manappuram Finance'!H24 -> 24735 | D23: ='Manappuram Finance'!I24 -> 29271 | E23: ='Manappuram Finance'!J24 -> 33690 | F23: ='Manappuram Finance'!K24 -> 56228 | G23: ='Muthoot Finance'!I24 -> 65030.642 | H23: ='Muthoot Finance'!J24 -> 77936 | I23: ='Muthoot Finance'!K24 -> 110254 | J23: ='Muthoot Finance'!L24 -> 163400 | K23: ='Muthoot Fincorp'!D24 -> 17585.782 | L23: ='Muthoot Fincorp'!E24 -> 21415 | M23: ='Muthoot Fincorp'!F24 -> 25752 | N23: ='Muthoot Fincorp'!G24 -> 46193 | O23: ='Muthoot MCred'!D24 -> 3263 | P23: ='Muthoot MCred'!E24 -> 3523 | Q23: ='Muthoot MCred'!F24 -> 4142 | R23: ='Muthoot MCred'!G24 -> 6625 | S23: ='Kosamattam Finance'!D24 -> 4910 | T23: ='Kosamattam Finance'!E24 -> 5383 | U23: ='Kosamattam Finance'!F24 -> 5766 | V23: ='Kosamattam Finance'!G24 -> 7786
B24: Gross NPAs | C24: ='Manappuram Finance'!H25 -> 321 | D24: ='Manappuram Finance'!I25 -> 547 | E24: ='Manappuram Finance'!J25 -> 891 | F24: ='Manappuram Finance'!K25 -> 991 | G24: ='Muthoot Finance'!I25 -> 2398.596 | H24: ='Muthoot Finance'!J25 -> 2485 | I24: ='Muthoot Finance'!K25 -> 3700 | J24: ='Muthoot Finance'!L25 -> 3824 | K24: ='Muthoot Fincorp'!D25 -> 371.6113 | L24: ='Muthoot Fincorp'!E25 -> 351 | M24: ='Muthoot Fincorp'!F25 -> 516 | N24: ='Muthoot Fincorp'!G25 -> 476 | O24: ='Muthoot MCred'!D25 -> 14 | P24: ='Muthoot MCred'!E25 -> 31 | Q24: ='Muthoot MCred'!F25 -> 35 | R24: ='Muthoot MCred'!G25 -> 41 | S24: ='Kosamattam Finance'!D25 -> 78 | T24: ='Kosamattam Finance'!E25 -> 78 | U24: ='Kosamattam Finance'!F25 -> 79 | V24: ='Kosamattam Finance'!G25 -> 94
B25: Net NPAs | C25: ='Manappuram Finance'!H26 -> 255 | D25: ='Manappuram Finance'!I26 -> 456 | E25: ='Manappuram Finance'!J26 -> 753 | F25: ='Manappuram Finance'!K26 -> 842 | G25: ='Muthoot Finance'!I26 -> 2152.124 | H25: ='Muthoot Finance'!J26 -> 2197 | I25: ='Muthoot Finance'!K26 -> 3037 | J25: ='Muthoot Finance'!L26 -> 3324 | K25: ='Muthoot Fincorp'!D26 -> 102.2142 | L25: ='Muthoot Fincorp'!E26 -> 139 | M25: ='Muthoot Fincorp'!F26 -> 332 | N25: ='Muthoot Fincorp'!G26 -> 263 | O25: ='Muthoot MCred'!D26 -> 12 | P25: ='Muthoot MCred'!E26 -> 25 | Q25: ='Muthoot MCred'!F26 -> 21 | R25: ='Muthoot MCred'!G26 -> 17 | S25: ='Kosamattam Finance'!D26 -> 33 | T25: ='Kosamattam Finance'!E26 -> 28 | U25: ='Kosamattam Finance'!F26 -> 27 | V25: ='Kosamattam Finance'!G26 -> 38
C27: ='Manappuram Finance'!N2 -> FY23 (A) | D27: ='Manappuram Finance'!O2 -> FY24 (A) | E27: ='Manappuram Finance'!P2 -> FY25 (A) | F27: ='Manappuram Finance'!Q2 -> FY26 (A) | G27: ='Muthoot Finance'!P3 -> FY23 (A) | H27: ='Muthoot Finance'!Q3 -> FY24 (A) | I27: ='Muthoot Finance'!R3 -> FY25 (A) | J27: ='Muthoot Finance'!S3 -> FY26 (A) | K27: ='Muthoot Fincorp'!K3 -> FY23 (A) | L27: ='Muthoot Fincorp'!L3 -> FY24 (A) | M27: ='Muthoot Fincorp'!M3 -> FY25 (A) | N27: ='Muthoot Fincorp'!N3 -> FY26 (A) | O27: ='Muthoot MCred'!K3 -> FY23 (A) | P27: ='Muthoot MCred'!L3 -> FY24 (A) | Q27: ='Muthoot MCred'!M3 -> FY25 (A) | R27: ='Muthoot MCred'!N3 -> FY26 (A) | S27: ='Kosamattam Finance'!K3 -> FY23 (A) | T27: ='Kosamattam Finance'!L3 -> FY24 (A) | U27: ='Kosamattam Finance'!M3 -> FY25 (A) | V27: ='Kosamattam Finance'!N3 -> FY26 (A)
B28: Profitability
B29: Net Interest Margin | C29: ='Manappuram Finance'!N4 -> 0.13312949 | D29: ='Manappuram Finance'!O4 -> 0.14114777 | E29: ='Manappuram Finance'!P4 -> 0.1387208 | F29: ='Manappuram Finance'!Q4 -> 0.099735314 | G29: ='Muthoot Finance'!P5 -> 0.10303727 | H29: ='Muthoot Finance'!Q5 -> 0.10535325 | I29: ='Muthoot Finance'!R5 -> 0.10730645 | J29: ='Muthoot Finance'!S5 -> 0.12515805 | K29: ='Muthoot Fincorp'!K4 -> 0.09931591 | L29: ='Muthoot Fincorp'!L4 -> 0.097946754 | M29: ='Muthoot Fincorp'!M4 -> 0.11122183 | N29: ='Muthoot Fincorp'!N4 -> 0.1295156 | O29: ='Muthoot MCred'!K4 -> 0.081921623 | P29: ='Muthoot MCred'!L4 -> 0.08311229 | Q29: ='Muthoot MCred'!M4 -> 0.090541422 | R29: ='Muthoot MCred'!N4 -> 0.095848426 | S29: ='Kosamattam Finance'!J4 -> 0.058619837 | T29: ='Kosamattam Finance'!K4 -> 0.073271529 | U29: ='Kosamattam Finance'!L4 -> 0.066452929 | V29: ='Kosamattam Finance'!M4 -> 0.063682842
B30: Capitalization
B31: Leverage (Debt/TNW) | C31: ='Manappuram Finance'!N6 -> 2.1413702 | D31: ='Manappuram Finance'!O6 -> 2.1928272 | E31: ='Manappuram Finance'!P6 -> 2.3852192 | F31: ='Manappuram Finance'!Q6 -> 3.1967534 | G31: ='Muthoot Finance'!P7 -> 2.3613369 | H31: ='Muthoot Finance'!Q7 -> 2.4237414 | I31: ='Muthoot Finance'!R7 -> 3.3610238 | J31: ='Muthoot Finance'!S7 -> 4.0621754 | K31: ='Muthoot Fincorp'!K6 -> 4.5782216 | L31: ='Muthoot Fincorp'!L6 -> 4.7842044 | M31: ='Muthoot Fincorp'!M6 -> 5.3752599 | N31: ='Muthoot Fincorp'!N6 -> 6.5292708 | O31: ='Muthoot MCred'!K6 -> 5.1559486 | P31: ='Muthoot MCred'!L6 -> 5.1084165 | Q31: ='Muthoot MCred'!M6 -> 5.1681305 | R31: ='Muthoot MCred'!N6 -> 5.4020708 | S31: ='Kosamattam Finance'!J6 -> 6.0372093 | T31: ='Kosamattam Finance'!K6 -> 6.1222076 | U31: ='Kosamattam Finance'!L6 -> 5.4835526 | V31: ='Kosamattam Finance'!M6 -> 5.0439351
B32: CAR | C32: ='Manappuram Finance'!N7 -> 0.317 | D32: ='Manappuram Finance'!O7 -> 0.3058 | E32: ='Manappuram Finance'!P7 -> 0.3091 | F32: ='Manappuram Finance'!Q7 -> 0.213 | G32: ='Muthoot Finance'!P8 -> 0.3177 | H32: ='Muthoot Finance'!Q8 -> 0 | I32: ='Muthoot Finance'!R8 -> 0 | J32: ='Muthoot Finance'!S8 -> 0 | K32: ='Muthoot Fincorp'!K7 -> 0.2134 | L32: 0.2001 | M32: 0.195 | N32: 0.18 | O32: ='Muthoot MCred'!K7 -> 0.2282 | P32: ='Muthoot MCred'!L7 -> 0.2386 | Q32: ='Muthoot MCred'!M7 -> 0.2138 | R32: ='Muthoot MCred'!N7 -> 0.1812 | S32: ='Kosamattam Finance'!J7 -> 0.1865 | T32: ='Kosamattam Finance'!K7 -> 0.1771 | U32: ='Kosamattam Finance'!L7 -> 0.1842 | V32: ='Kosamattam Finance'!M7 -> 0.1878
B33: TNW/Loan Book | C33: ='Manappuram Finance'!N8 -> 0.36305093 | D33: ='Manappuram Finance'!O8 -> 0.34907521 | E33: ='Manappuram Finance'!P8 -> 0.33656871 | F33: ='Manappuram Finance'!Q8 -> 0.2815679 | G33: ='Muthoot Finance'!P9 -> 0.32387698 | H33: ='Muthoot Finance'!Q9 -> 0.31119123 | I33: ='Muthoot Finance'!R9 -> 0.24238576 | J33: ='Muthoot Finance'!S9 -> 0.20857405 | K33: ='Muthoot Fincorp'!K8 -> 0.22137398 | L33: ='Muthoot Fincorp'!L8 -> 0.20102732 | M33: ='Muthoot Fincorp'!M8 -> 0.18678161 | N33: ='Muthoot Fincorp'!N8 -> 0.14458901 | O33: ='Muthoot MCred'!K8 -> 0.19062213 | P33: ='Muthoot MCred'!L8 -> 0.19897814 | Q33: ='Muthoot MCred'!M8 -> 0.19241912 | R33: ='Muthoot MCred'!N8 -> 0.1749434 | S33: ='Kosamattam Finance'!J8 -> 0.159535 | T33: ='Kosamattam Finance'!K8 -> 0.15498982 | U33: ='Kosamattam Finance'!L8 -> 0.16942226 | V33: ='Kosamattam Finance'!M8 -> 0.18158169
B34: Operational Efficiency
